<?xml version="1.0" encoding="utf-8"?>
<!-- This URDF was automatically created by SolidWorks to URDF Exporter! Originally created by Stephen Brawner (brawner@gmail.com) 
     Commit Version: 1.6.0-4-g7f85cfe  Build Version: 1.6.7995.38578
     For more information, please see http://wiki.ros.org/sw_urdf_exporter -->
<robot
  name="double_urdf_1115">
  <link
    name="base_link">
    <inertial>
      <origin
        xyz="0.0014924 -3.6009E-07 0.0071665"
        rpy="0 0 0" />
      <mass
        value="0.26633" />
      <inertia
        ixx="0.001015"
        ixy="-1.6437E-08"
        ixz="2.8422E-06"
        iyy="0.00087826"
        iyz="-1.5352E-09"
        izz="0.0009477" />
    </inertial>
    <visual>
      <origin
        xyz="0 0 0"
        rpy="0 0 0" />
      <geometry>
        <mesh
          filename="package://double_urdf_1115/meshes/base_link.STL" />
      </geometry>
      <material
        name="">
        <color
          rgba="1 1 1 1" />
      </material>
    </visual>
    <collision>
      <origin
        xyz="0 0 0"
        rpy="0 0 0" />
      <geometry>
        <mesh
          filename="package://double_urdf_1115/meshes/base_link.STL" />
      </geometry>
    </collision>
  </link>
  <link
    name="Empty_Link1">
    <inertial>
      <origin
        xyz="1.3342E-15 -1.4314E-16 -0.045037"
        rpy="0 0 0" />
      <mass
        value="0.13934" />
      <inertia
        ixx="0.00027154"
        ixy="-1.0009E-19"
        ixz="1.8873E-20"
        iyy="0.00027154"
        iyz="2.3247E-20"
        izz="0.0002872" />
    </inertial>
    <visual>
      <origin
        xyz="0 0 0"
        rpy="0 0 0" />
      <geometry>
        <mesh
          filename="package://double_urdf_1115/meshes/Empty_Link1.STL" />
      </geometry>
      <material
        name="">
        <color
          rgba="1 1 1 1" />
      </material>
    </visual>
    <collision>
      <origin
        xyz="0 0 0"
        rpy="0 0 0" />
      <geometry>
        <mesh
          filename="package://double_urdf_1115/meshes/Empty_Link1.STL" />
      </geometry>
    </collision>
  </link>
  <joint
    name="joint1"
    type="revolute">
    <origin
      xyz="0 0.155 0"
      rpy="-1.5708 0 0" />
    <parent
      link="base_link" />
    <child
      link="Empty_Link1" />
    <axis
      xyz="0 0 1" />
    <limit
      lower="-3.14"
      upper="3.14"
      effort="0"
      velocity="0" />
  </joint>
  <link
    name="Empty_Link2">
    <inertial>
      <origin
        xyz="7.166E-06 -0.048549 -0.0068856"
        rpy="0 0 0" />
      <mass
        value="0.18506" />
      <inertia
        ixx="0.00057474"
        ixy="1.582E-08"
        ixz="1.5257E-08"
        iyy="0.00030975"
        iyz="2.2393E-05"
        izz="0.00060015" />
    </inertial>
    <visual>
      <origin
        xyz="0 0 0"
        rpy="0 0 0" />
      <geometry>
        <mesh
          filename="package://double_urdf_1115/meshes/Empty_Link2.STL" />
      </geometry>
      <material
        name="">
        <color
          rgba="0.79216 0.81961 0.93333 1" />
      </material>
    </visual>
    <collision>
      <origin
        xyz="0 0 0"
        rpy="0 0 0" />
      <geometry>
        <mesh
          filename="package://double_urdf_1115/meshes/Empty_Link2.STL" />
      </geometry>
    </collision>
  </link>
  <joint
    name="joint2"
    type="revolute">
    <origin
      xyz="0 -0.00035 0.11922"
      rpy="1.5708 0 0" />
    <parent
      link="Empty_Link1" />
    <child
      link="Empty_Link2" />
    <axis
      xyz="0 0 1" />
    <limit
      lower="-3.14"
      upper="3.14"
      effort="0"
      velocity="0" />
  </joint>
  <link
    name="Empty_Link3">
    <inertial>
      <origin
        xyz="5.8184E-05 -0.016095 -0.091281"
        rpy="0 0 0" />
      <mass
        value="0.17747" />
      <inertia
        ixx="0.00082408"
        ixy="-1.8121E-07"
        ixz="3.8226E-07"
        iyy="0.00083188"
        iyz="-0.00014581"
        izz="0.00032099" />
    </inertial>
    <visual>
      <origin
        xyz="0 0 0"
        rpy="0 0 0" />
      <geometry>
        <mesh
          filename="package://double_urdf_1115/meshes/Empty_Link3.STL" />
      </geometry>
      <material
        name="">
        <color
          rgba="0.4 0.4 0.4 1" />
      </material>
    </visual>
    <collision>
      <origin
        xyz="0 0 0"
        rpy="0 0 0" />
      <geometry>
        <mesh
          filename="package://double_urdf_1115/meshes/Empty_Link3.STL" />
      </geometry>
    </collision>
  </link>
  <joint
    name="joint3"
    type="revolute">
    <origin
      xyz="0 0.15914 -0.00045174"
      rpy="-1.5708 0 0" />
    <parent
      link="Empty_Link2" />
    <child
      link="Empty_Link3" />
    <axis
      xyz="0 0 1" />
    <limit
      lower="-3.14"
      upper="3.14"
      effort="0"
      velocity="0" />
  </joint>
  <link
    name="Empty_Link4">
    <inertial>
      <origin
        xyz="-2.34690957390065E-05 0.0530429982897136 -0.0344936012786148"
        rpy="0 0 0" />
      <mass
        value="0.16192408835113" />
      <inertia
        ixx="0.000592553537026838"
        ixy="1.24920714247319E-07"
        ixz="-2.56857673520256E-08"
        iyy="0.000284690856489502"
        iyz="-1.56663424512197E-05"
        izz="0.000621255050385904" />
    </inertial>
    <visual>
      <origin
        xyz="0 0 0"
        rpy="0 0 0" />
      <geometry>
        <mesh
          filename="package://double_urdf_1115/meshes/Empty_Link4.STL" />
      </geometry>
      <material
        name="">
        <color
          rgba="0.792156862745098 0.819607843137255 0.933333333333333 1" />
      </material>
    </visual>
    <collision>
      <origin
        xyz="0 0 0"
        rpy="0 0 0" />
      <geometry>
        <mesh
          filename="package://double_urdf_1115/meshes/Empty_Link4.STL" />
      </geometry>
    </collision>
  </link>
  <joint
    name="joint4"
    type="revolute">
    <origin
      xyz="-0.00021415 0.027937 0.141"
      rpy="-1.5708 0 0" />
    <parent
      link="Empty_Link3" />
    <child
      link="Empty_Link4" />
    <axis
      xyz="0 0 1" />
    <limit
      lower="-3.14"
      upper="3.14"
      effort="0"
      velocity="0" />
  </joint>
  <link
    name="Empty_Link5">
    <inertial>
      <origin
        xyz="1.04535537986443E-05 0.0186156117776231 -0.0808695350497136"
        rpy="0 0 0" />
      <mass
        value="0.168807323609659" />
      <inertia
        ixx="0.000595652486887033"
        ixy="-1.15153474040901E-08"
        ixz="3.52118443057937E-08"
        iyy="0.000609012231195647"
        iyz="0.000119225841892786"
        izz="0.000286029197228179" />
    </inertial>
    <visual>
      <origin
        xyz="0 0 0"
        rpy="0 0 0" />
      <geometry>
        <mesh
          filename="package://double_urdf_1115/meshes/Empty_Link5.STL" />
      </geometry>
      <material
        name="">
        <color
          rgba="0.592156862745098 0.666666666666667 0.682352941176471 1" />
      </material>
    </visual>
    <collision>
      <origin
        xyz="0 0 0"
        rpy="0 0 0" />
      <geometry>
        <mesh
          filename="package://double_urdf_1115/meshes/Empty_Link5.STL" />
      </geometry>
    </collision>
  </link>
  <joint
    name="joint5"
    type="revolute">
    <origin
      xyz="0 -0.13261 -0.028113"
      rpy="1.5708 0 0" />
    <parent
      link="Empty_Link4" />
    <child
      link="Empty_Link5" />
    <axis
      xyz="0 0 1" />
    <limit
      lower="-3.14"
      upper="3.14"
      effort="0"
      velocity="0" />
  </joint>
  <link
    name="Empty_Link6">
    <inertial>
      <origin
        xyz="-5.37742704261599E-06 -0.0294879271262189 -0.0050268422920796"
        rpy="0 0 0" />
      <mass
        value="0.117396065677008" />
      <inertia
        ixx="0.000223870432302695"
        ixy="7.95027783487269E-09"
        ixz="-5.72128501019399E-09"
        iyy="0.000157599697987618"
        iyz="-2.17977047320675E-06"
        izz="0.000247478280617227" />
    </inertial>
    <visual>
      <origin
        xyz="0 0 0"
        rpy="0 0 0" />
      <geometry>
        <mesh
          filename="package://double_urdf_1115/meshes/Empty_Link6.STL" />
      </geometry>
      <material
        name="">
        <color
          rgba="0.792156862745098 0.819607843137255 0.933333333333333 1" />
      </material>
    </visual>
    <collision>
      <origin
        xyz="0 0 0"
        rpy="0 0 0" />
      <geometry>
        <mesh
          filename="package://double_urdf_1115/meshes/Empty_Link6.STL" />
      </geometry>
    </collision>
  </link>
  <joint
    name="joint6"
    type="revolute">
    <origin
      xyz="0 0.00015973 0.0874"
      rpy="1.5708 0 0" />
    <parent
      link="Empty_Link5" />
    <child
      link="Empty_Link6" />
    <axis
      xyz="0 0 1" />
    <limit
      lower="-3.14"
      upper="3.14"
      effort="0"
      velocity="0" />
  </joint>
  <link
    name="Empty_Link7">
    <inertial>
      <origin
        xyz="-3.59625462130323E-05 -0.0148085138766828 -0.0803302114956457"
        rpy="0 0 0" />
      <mass
        value="0.142755944866628" />
      <inertia
        ixx="0.000464416842224509"
        ixy="-1.13125801258198E-07"
        ixz="-2.41633988960636E-07"
        iyy="0.000477322772947618"
        iyz="-8.04893326122221E-05"
        izz="0.000208248311212371" />
    </inertial>
    <visual>
      <origin
        xyz="0 0 0"
        rpy="0 0 0" />
      <geometry>
        <mesh
          filename="package://double_urdf_1115/meshes/Empty_Link7.STL" />
      </geometry>
      <material
        name="">
        <color
          rgba="0.207843137254902 0.376470588235294 0.568627450980392 1" />
      </material>
    </visual>
    <collision>
      <origin
        xyz="0 0 0"
        rpy="0 0 0" />
      <geometry>
        <mesh
          filename="package://double_urdf_1115/meshes/Empty_Link7.STL" />
      </geometry>
    </collision>
  </link>
  <joint
    name="joint7"
    type="revolute">
    <origin
      xyz="0 0.13012 6.068E-05"
      rpy="-1.5708 0 0" />
    <parent
      link="Empty_Link6" />
    <child
      link="Empty_Link7" />
    <axis
      xyz="0 0 1" />
    <limit
      lower="-3.14"
      upper="3.14"
      effort="0"
      velocity="0" />
  </joint>
  <link
    name="Empty_Link8">
    <inertial>
      <origin
        xyz="1.49721899678073E-17 1.21212098202637E-17 -0.0450366643520861"
        rpy="0 0 0" />
      <mass
        value="0.139340614702608" />
      <inertia
        ixx="0.000271543617515806"
        ixy="0"
        ixz="3.28941289409917E-20"
        iyy="0.000271543617515806"
        iyz="-1.90269046791232E-20"
        izz="0.000287198405303248" />
    </inertial>
    <visual>
      <origin
        xyz="0 0 0"
        rpy="0 0 0" />
      <geometry>
        <mesh
          filename="package://double_urdf_1115/meshes/Empty_Link8.STL" />
      </geometry>
      <material
        name="">
        <color
          rgba="1 1 1 1" />
      </material>
    </visual>
    <collision>
      <origin
        xyz="0 0 0"
        rpy="0 0 0" />
      <geometry>
        <mesh
          filename="package://double_urdf_1115/meshes/Empty_Link8.STL" />
      </geometry>
    </collision>
  </link>
  <joint
    name="joint8"
    type="revolute">
    <origin
      xyz="0 -0.155 0"
      rpy="1.5708 0 0" />
    <parent
      link="base_link" />
    <child
      link="Empty_Link8" />
    <axis
      xyz="0 0 1" />
    <limit
      lower="-3.14"
      upper="3.14"
      effort="0"
      velocity="0" />
  </joint>
  <link
    name="Empty_Link9">
    <inertial>
      <origin
        xyz="-7.16594927825932E-06 0.0485485652046426 -0.00688560464007289"
        rpy="0 0 0" />
      <mass
        value="0.185060518932336" />
      <inertia
        ixx="0.000574743039604598"
        ixy="1.58201859118487E-08"
        ixz="-1.52565385581314E-08"
        iyy="0.000309754503746068"
        iyz="-2.23925932297582E-05"
        izz="0.000600146186131235" />
    </inertial>
    <visual>
      <origin
        xyz="0 0 0"
        rpy="0 0 0" />
      <geometry>
        <mesh
          filename="package://double_urdf_1115/meshes/Empty_Link9.STL" />
      </geometry>
      <material
        name="">
        <color
          rgba="0.792156862745098 0.819607843137255 0.933333333333333 1" />
      </material>
    </visual>
    <collision>
      <origin
        xyz="0 0 0"
        rpy="0 0 0" />
      <geometry>
        <mesh
          filename="package://double_urdf_1115/meshes/Empty_Link9.STL" />
      </geometry>
    </collision>
  </link>
  <joint
    name="joint9"
    type="revolute">
    <origin
      xyz="-0.00031688 0.00014862 0.11922"
      rpy="-1.5708 0 0" />
    <parent
      link="Empty_Link8" />
    <child
      link="Empty_Link9" />
    <axis
      xyz="0 0 1" />
    <limit
      lower="-3.14"
      upper="3.14"
      effort="0"
      velocity="0" />
  </joint>
  <link
    name="Empty_Link10">
    <inertial>
      <origin
        xyz="-5.94384826685485E-05 0.0160958771905672 -0.0912820049952374"
        rpy="0 0 0" />
      <mass
        value="0.177472851336342" />
      <inertia
        ixx="0.000824077447613594"
        ixy="-1.72307611943163E-07"
        ixz="-3.71042895258372E-07"
        iyy="0.000831872702963459"
        iyz="0.000145819419475302"
        izz="0.000320999323188475" />
    </inertial>
    <visual>
      <origin
        xyz="0 0 0"
        rpy="0 0 0" />
      <geometry>
        <mesh
          filename="package://double_urdf_1115/meshes/Empty_Link10.STL" />
      </geometry>
      <material
        name="">
        <color
          rgba="0.4 0.4 0.4 1" />
      </material>
    </visual>
    <collision>
      <origin
        xyz="0 0 0"
        rpy="0 0 0" />
      <geometry>
        <mesh
          filename="package://double_urdf_1115/meshes/Empty_Link10.STL" />
      </geometry>
    </collision>
  </link>
  <joint
    name="joint10"
    type="revolute">
    <origin
      xyz="0 -0.15914 -0.00045174"
      rpy="1.5708 0 0" />
    <parent
      link="Empty_Link9" />
    <child
      link="Empty_Link10" />
    <axis
      xyz="0 0 1" />
    <limit
      lower="-3.14"
      upper="3.14"
      effort="0"
      velocity="0" />
  </joint>
  <link
    name="Empty_Link11">
    <inertial>
      <origin
        xyz="2.34441480310305E-05 -0.0530429302263745 -0.0344937239635185"
        rpy="0 0 0" />
      <mass
        value="0.161924001999403" />
      <inertia
        ixx="0.000592552353330134"
        ixy="1.2434344296049E-07"
        ixz="2.63003230418194E-08"
        iyy="0.000284690451366544"
        iyz="1.56656637680802E-05"
        izz="0.000621253748082398" />
    </inertial>
    <visual>
      <origin
        xyz="0 0 0"
        rpy="0 0 0" />
      <geometry>
        <mesh
          filename="package://double_urdf_1115/meshes/Empty_Link11.STL" />
      </geometry>
      <material
        name="">
        <color
          rgba="0.792156862745098 0.819607843137255 0.933333333333333 1" />
      </material>
    </visual>
    <collision>
      <origin
        xyz="0 0 0"
        rpy="0 0 0" />
      <geometry>
        <mesh
          filename="package://double_urdf_1115/meshes/Empty_Link11.STL" />
      </geometry>
    </collision>
  </link>
  <joint
    name="joint11"
    type="revolute">
    <origin
      xyz="0.00021415 -0.027937 0.141"
      rpy="1.5708 0 0" />
    <parent
      link="Empty_Link10" />
    <child
      link="Empty_Link11" />
    <axis
      xyz="0 0 1" />
    <limit
      lower="-3.14"
      upper="3.14"
      effort="0"
      velocity="0" />
  </joint>
  <link
    name="Empty_Link12">
    <inertial>
      <origin
        xyz="-1.04514586418068E-05 -0.0186156122160094 -0.0808695354091304"
        rpy="0 0 0" />
      <mass
        value="0.168807314881665" />
      <inertia
        ixx="0.000595652505520319"
        ixy="-1.15092010285501E-08"
        ixz="-3.52119149028543E-08"
        iyy="0.000609012222102752"
        iyz="-0.000119225846097008"
        izz="0.000286029204756189" />
    </inertial>
    <visual>
      <origin
        xyz="0 0 0"
        rpy="0 0 0" />
      <geometry>
        <mesh
          filename="package://double_urdf_1115/meshes/Empty_Link12.STL" />
      </geometry>
      <material
        name="">
        <color
          rgba="0.592156862745098 0.666666666666667 0.682352941176471 1" />
      </material>
    </visual>
    <collision>
      <origin
        xyz="0 0 0"
        rpy="0 0 0" />
      <geometry>
        <mesh
          filename="package://double_urdf_1115/meshes/Empty_Link12.STL" />
      </geometry>
    </collision>
  </link>
  <joint
    name="joint12"
    type="revolute">
    <origin
      xyz="0 0.13261 -0.028113"
      rpy="-1.5708 0 0" />
    <parent
      link="Empty_Link11" />
    <child
      link="Empty_Link12" />
    <axis
      xyz="0 0 1" />
    <limit
      lower="-3.14"
      upper="3.14"
      effort="0"
      velocity="0" />
  </joint>
  <link
    name="Empty_Link13">
    <inertial>
      <origin
        xyz="5.40421941918373E-06 0.0294879292709374 -0.00502683974917504"
        rpy="0 0 0" />
      <mass
        value="0.117396053955842" />
      <inertia
        ixx="0.000223870417500324"
        ixy="8.02611360782286E-09"
        ixz="5.79779807908504E-09"
        iyy="0.000157599679542628"
        iyz="2.17977735443414E-06"
        izz="0.00024747826441045" />
    </inertial>
    <visual>
      <origin
        xyz="0 0 0"
        rpy="0 0 0" />
      <geometry>
        <mesh
          filename="package://double_urdf_1115/meshes/Empty_Link13.STL" />
      </geometry>
      <material
        name="">
        <color
          rgba="0.792156862745098 0.819607843137255 0.933333333333333 1" />
      </material>
    </visual>
    <collision>
      <origin
        xyz="0 0 0"
        rpy="0 0 0" />
      <geometry>
        <mesh
          filename="package://double_urdf_1115/meshes/Empty_Link13.STL" />
      </geometry>
    </collision>
  </link>
  <joint
    name="joint13"
    type="revolute">
    <origin
      xyz="0 -0.00015973 0.0874"
      rpy="-1.5708 0 0" />
    <parent
      link="Empty_Link12" />
    <child
      link="Empty_Link13" />
    <axis
      xyz="0 0 1" />
    <limit
      lower="-3.14"
      upper="3.14"
      effort="0"
      velocity="0" />
  </joint>
  <link
    name="Empty_Link14">
    <inertial>
      <origin
        xyz="3.5981E-05 0.014808 -0.08033"
        rpy="0 0 0" />
      <mass
        value="0.14276" />
      <inertia
        ixx="0.00046442"
        ixy="-1.1306E-07"
        ixz="2.4166E-07"
        iyy="0.00047732"
        iyz="8.0489E-05"
        izz="0.00020825" />
    </inertial>
    <visual>
      <origin
        xyz="0 0 0"
        rpy="0 0 0" />
      <geometry>
        <mesh
          filename="package://double_urdf_1115/meshes/Empty_Link14.STL" />
      </geometry>
      <material
        name="">
        <color
          rgba="0.20784 0.37647 0.56863 1" />
      </material>
    </visual>
    <collision>
      <origin
        xyz="0 0 0"
        rpy="0 0 0" />
      <geometry>
        <mesh
          filename="package://double_urdf_1115/meshes/Empty_Link14.STL" />
      </geometry>
    </collision>
  </link>
  <joint
    name="joint14"
    type="revolute">
    <origin
      xyz="0 -0.13012 6.068E-05"
      rpy="1.5708 0 0" />
    <parent
      link="Empty_Link13" />
    <child
      link="Empty_Link14" />
    <axis
      xyz="0 0 1" />
    <limit
      lower="-3.14"
      upper="3.14"
      effort="0"
      velocity="0" />
  </joint>
</robot>
